<?xml version="1.0" encoding="utf-8"?>
<robot name="d1_550_description">

    <!-- D1 Base Link -->
    <link name="d1_base_link">
        <inertial>
            <origin xyz="-9.0106E-05 -0.00012378 0.033469" rpy="0 0 0" />
            <mass value="0.16964" />
            <inertia ixx="0.00030483" ixy="1.2051E-06" ixz="3.9736E-06" iyy="0.00031037" iyz="8.0144E-07" izz="0.00050913" />
        </inertial>
        <visual>
            <origin xyz="0 0 0" rpy="0 0 0" />
            <geometry>
                <mesh filename="package://go2_description/meshes/d1/unitree/d1_base_link.stl" />
            </geometry>
            <material name="dark_grey">
                <color rgba="0.2 0.2 0.2 1" />
            </material>
        </visual>
        <collision>
            <origin xyz="0 0 0" rpy="0 0 0" />
            <geometry>
                <mesh filename="package://go2_description/meshes/d1/unitree/d1_base_link.stl" />
            </geometry>
        </collision>
    </link>
    <joint name="d1_base_joint" type="fixed">
        <origin xyz='0 0.046 0.14' rpy="0 0 -1.57" />
        <parent link="computer_dock_link" />
        <child link="d1_base_link" />
    </joint>

    <!-- D1 Link1 -->
    <link name="d1_link1">
        <inertial>
            <origin xyz="-0.0030892 6.1834E-05 0.031665" rpy="0 0 0" />
            <mass value="0.14706" />
            <inertia ixx="7.8054E-05" ixy="1.9698E-10" ixz="-1.574E-08" iyy="6.6897E-05" iyz="-4.3439E-09" izz="7.0773E-05" />
        </inertial>
        <visual>
            <origin xyz="0 0 0" rpy="0 0 0" />
            <geometry>
                <mesh filename="package://go2_description/meshes/d1/unitree/d1_link1.stl" />
            </geometry>
            <material name="dark_grey">
                <color rgba="0.2 0.2 0.2 1" />
            </material>
        </visual>
        <collision>
            <origin xyz="0 0 0" rpy="0 0 0" />
            <geometry>
                <mesh filename="package://go2_description/meshes/d1/unitree/d1_link1.stl" />
            </geometry>
        </collision>
    </link>
    <joint name="d1_link1_joint" type="revolute">
        <origin xyz="0 0 0.0738" rpy="0 0 0" />
        <parent link="d1_base_link" />
        <child link="d1_link1" />
        <axis xyz="0 0 -1" />
        <limit lower="-2.36" upper="2.36" effort="3.33" velocity="1.05" />
    </joint>

    <!-- D1 Link2-->
    <link name="d1_link2">
        <inertial>
            <origin xyz="5.7801E-05 0.027243 0.19413" rpy="0 0 0" />
            <mass value="0.20987" />
            <inertia ixx="0.00025832" ixy="-2.101E-11" ixz="-1.4864E-07" iyy="0.00023175" iyz="-4.425E-09" izz="6.5679E-05" />
        </inertial>
        <visual>
            <origin xyz="0 0 0" rpy="0 0 0" />
            <geometry>
                <mesh filename="package://go2_description/meshes/d1/unitree/d1_link2.stl" />
            </geometry>
            <material name="dark_grey">
                <color rgba="0.2 0.2 0.2 1" />
            </material>
        </visual>
        <collision>
            <origin xyz="0 0 0" rpy="0 0 0" />
            <geometry>
                <mesh filename="package://go2_description/meshes/d1/unitree/d1_link2.stl" />
            </geometry>
        </collision>
    </link>
    <joint name="d1_link2_joint" type="revolute">
        <origin xyz="0 -0.0276 0.0578" rpy="0 0 0" />
        <parent link="d1_link1" />
        <child link="d1_link2" />
        <axis xyz="0 1 0" />
        <limit lower="-1.57" upper="1.57" effort="3.33" velocity="1.05" />
    </joint>

    <!-- D1 Link3 -->
    <link name="d1_link3">
        <inertial>
            <origin xyz="0.016105 0.0275 0.044231" rpy="0 0 0" />
            <mass value="0.064921" />
            <inertia ixx="2.0648E-05" ixy="-3.9865E-11" ixz="-2.0913E-06" iyy="1.6024E-05" iyz="-5.5601E-11" izz="1.2186E-05" />
        </inertial>
        <visual>
            <origin xyz="0 0 0" rpy="0 0 0" />
            <geometry>
                <mesh filename="package://go2_description/meshes/d1/unitree/d1_link3.stl" />
            </geometry>
            <material name="dark_grey">
                <color rgba="0.2 0.2 0.2 1" />
            </material>
        </visual>
        <collision>
            <origin xyz="0 0 0" rpy="0 0 0" />
            <geometry>
                <mesh filename="package://go2_description/meshes/d1/unitree/d1_link3.stl" />
            </geometry>
        </collision>
    </link>
    <joint name="d1_link3_joint" type="revolute">
        <origin xyz="0 -0.0004 0.27" rpy="0 0 0" />
        <parent link="d1_link2" />
        <child link="d1_link3" />
        <axis xyz="0 1 0" />
        <limit lower="-1.57" upper="1.57" effort="3.33" velocity="1.05" />
    </joint>

    <!-- D1 Link4 -->
    <link name="d1_link4">
        <inertial>
            <origin xyz="0.096072 3.157E-05 0.00025559" rpy="0 0 0" />
            <mass value="0.081362" />
            <inertia ixx="1.6724E-05" ixy="-5.5957E-08" ixz="9.45E-08" iyy="5.1663E-05" iyz="1.6089E-12" izz="6.1415E-05" />
        </inertial>
        <visual>
            <origin xyz="0 0 0" rpy="0 0 0" />
            <geometry>
                <mesh filename="package://go2_description/meshes/d1/unitree/d1_link4.stl" />
            </geometry>
            <material name="dark_grey">
                <color rgba="0.2 0.2 0.2 1" />
            </material>
        </visual>
        <collision>
            <origin xyz="0 0 0" rpy="0 0 0" />
            <geometry>
                <mesh filename="package://go2_description/meshes/d1/unitree/d1_link4.stl" />
            </geometry>
        </collision>
    </link>
    <joint name="d1_link4_joint" type="revolute">
        <origin xyz="0.05 0.0275 0.041325" rpy="0 0 0" />
        <parent link="d1_link3" />
        <child link="d1_link4" />
        <axis xyz="1 0 0" />
        <limit lower="-2.36" upper="2.36" effort="1.67" velocity="1.73" />
    </joint>

    <!-- D1 Link5 -->
    <link name="d1_link5">
        <inertial>
            <origin xyz="0.044211 0.025813 0.0054296" rpy="0 0 0" />
            <mass value="0.059846" />
            <inertia ixx="1.4667E-05" ixy="-4.9109E-10" ixz="-4.7057E-07" iyy="1.2009E-05" iyz="1.4753E-09" izz="9.9767E-06" />
        </inertial>
        <visual>
            <origin xyz="0 0 0" rpy="0 0 0" />
            <geometry>
                <mesh filename="package://go2_description/meshes/d1/unitree/d1_link5.stl" />
            </geometry>
            <material name="dark_grey">
                <color rgba="0.2 0.2 0.2 1" />
            </material>
        </visual>
        <collision>
            <origin xyz="0 0 0" rpy="0 0 0" />
            <geometry>
                <mesh filename="package://go2_description/meshes/d1/unitree/d1_link5.stl" />
            </geometry>
        </collision>
    </link>
    <joint name="d1_link5_joint" type="revolute">
        <origin xyz="0.15468 -0.0258 0.0001" rpy="0 0 0" />
        <parent link="d1_link4" />
        <child link="d1_link5" />
        <axis xyz="0 1 0" />
        <limit lower="-1.57" upper="1.57" effort="1.67" velocity="1.73" />
    </joint>

    <!-- D1 Link6 -->
    <link name="d1_link6">
        <inertial>
            <origin xyz="0.03844 -0.00044094 0.0060952" rpy="0 0 0" />
            <mass value="0.12117" />
            <inertia ixx="0.00011988" ixy="-9.0166E-08" ixz="1.1937E-06" iyy="3.2466E-05" iyz="-2.1696E-09" izz="0.0001058" />
        </inertial>
        <visual>
            <origin xyz="0 0 0" rpy="0 0 0" />
            <geometry>
                <mesh filename="package://go2_description/meshes/d1/unitree/d1_link6.stl" />
            </geometry>
            <material name="dark_grey">
                <color rgba="0.2 0.2 0.2 1" />
            </material>
        </visual>
        <collision>
            <origin xyz="0 0 0" rpy="0 0 0" />
            <geometry>
                <mesh filename="package://go2_description/meshes/d1/unitree/d1_link6.stl" />
            </geometry>
        </collision>
    </link>
    <joint name="d1_link6_joint" type="revolute">
        <origin xyz="0.0777 0.025822 -0.0010718" rpy="0 0 0" />
        <parent link="d1_link5" />
        <child link="d1_link6" />
        <axis xyz="1 0 0" />
        <limit lower="-2.36" upper="2.36" effort="1.67" velocity="1.73" />
    </joint>

    <!-- D1 Link L -->
    <link name="d1_link_l">
        <inertial>
            <origin xyz="0.018562 -0.0073492 -0.0034988" rpy="0 0 0" />
            <mass value="0.01333" />
            <inertia ixx="1.0229E-06" ixy="-1.5002E-07" ixz="1.3407E-11" iyy="2.3789E-06" iyz="-1.3846E-14" izz="1.8134E-06" />
        </inertial>
        <visual>
            <origin xyz="0 0 0" rpy="0 0 0" />
            <geometry>
                <mesh filename="package://go2_description/meshes/d1/unitree/d1_link_l.stl" />
            </geometry>
            <material name="dark_grey">
                <color rgba="0.2 0.2 0.2 1" />
            </material>
        </visual>
        <collision>
            <origin xyz="0 0 0" rpy="0 0 0" />
            <geometry>
                <mesh filename="package://go2_description/meshes/d1/unitree/d1_link_l.stl" />
            </geometry>
        </collision>
    </link>
    <joint name="d1_link_l_joint" type="prismatic">
        <origin xyz="0.0718 -0.033778 0.0031" rpy="0 0 0" />
        <parent link="d1_link6" />
        <child link="d1_link_l" />
        <axis xyz="0 1 0" />
        <limit lower="0" upper="0.033" effort="15" velocity="0.02" />
    </joint>

    <!-- D1 Link R -->
    <link name="d1_link_r">
        <inertial>
            <origin xyz="0.018562 0.0073492 -0.0035012" rpy="0 0 0" />
            <mass value="0.01333" />
            <inertia ixx="1.0229E-06" ixy="1.5002E-07" ixz="-1.3407E-11" iyy="2.3789E-06" iyz="-1.3811E-14" izz="1.8134E-06" />
        </inertial>
        <visual>
            <origin xyz="0 0 0" rpy="0 0 0" />
            <geometry>
                <mesh filename="package://go2_description/meshes/d1/unitree/d1_link_r.stl" />
            </geometry>
            <material name="dark_grey">
                <color rgba="0.2 0.2 0.2 1" />
            </material>
        </visual>
        <collision>
            <origin xyz="0 0 0" rpy="0 0 0" />
            <geometry>
                <mesh filename="package://go2_description/meshes/d1/unitree/d1_link_r.stl" />
            </geometry>
        </collision>
    </link>
    <joint name="d1_link_r_joint" type="prismatic">
        <origin xyz="0.0718 0.033022 0.0031" rpy="0 0 0" />
        <parent link="d1_link6" />
        <child link="d1_link_r" />
        <axis xyz="0 -1 0" />
        <limit lower="0" upper="0.033" effort="15" velocity="0.02" />
    </joint>
</robot>